 * Running on http://0.0.0.0:5000/ (Press CTRL+C to quit)
Traceback (most recent call last):
  File "app.py", line 77, in <module>
    main()
  File "app.py", line 74, in main
    app.run(host=HOST, port=PORT,debug=True)
  File "/Library/Frameworks/Python.framework/Versions/2.7/lib/python2.7/site-packages/flask/app.py", line 772, in run
    run_simple(host, port, self, **options)
  File "/Library/Frameworks/Python.framework/Versions/2.7/lib/python2.7/site-packages/werkzeug/serving.py", line 618, in run_simple
    test_socket.bind((hostname, port))
  File "/Library/Frameworks/Python.framework/Versions/2.7/lib/python2.7/socket.py", line 228, in meth
    return getattr(self._sock,name)(*args)
socket.error: [Errno 48] Address already in use
 * Running on http://0.0.0.0:5000/ (Press CTRL+C to quit)
Traceback (most recent call last):
  File "app.py", line 77, in <module>
    main()
  File "app.py", line 74, in main
    app.run(host=HOST, port=PORT,debug=False)
  File "/Library/Frameworks/Python.framework/Versions/2.7/lib/python2.7/site-packages/flask/app.py", line 772, in run
    run_simple(host, port, self, **options)
  File "/Library/Frameworks/Python.framework/Versions/2.7/lib/python2.7/site-packages/werkzeug/serving.py", line 625, in run_simple
    inner()
  File "/Library/Frameworks/Python.framework/Versions/2.7/lib/python2.7/site-packages/werkzeug/serving.py", line 603, in inner
    passthrough_errors, ssl_context).serve_forever()
  File "/Library/Frameworks/Python.framework/Versions/2.7/lib/python2.7/site-packages/werkzeug/serving.py", line 512, in make_server
    passthrough_errors, ssl_context)
  File "/Library/Frameworks/Python.framework/Versions/2.7/lib/python2.7/site-packages/werkzeug/serving.py", line 440, in __init__
    HTTPServer.__init__(self, (host, int(port)), handler)
  File "/Library/Frameworks/Python.framework/Versions/2.7/lib/python2.7/SocketServer.py", line 420, in __init__
    self.server_bind()
  File "/Library/Frameworks/Python.framework/Versions/2.7/lib/python2.7/BaseHTTPServer.py", line 108, in server_bind
    SocketServer.TCPServer.server_bind(self)
  File "/Library/Frameworks/Python.framework/Versions/2.7/lib/python2.7/SocketServer.py", line 434, in server_bind
    self.socket.bind(self.server_address)
  File "/Library/Frameworks/Python.framework/Versions/2.7/lib/python2.7/socket.py", line 228, in meth
    return getattr(self._sock,name)(*args)
socket.error: [Errno 48] Address already in use
 * Running on http://0.0.0.0:5000/ (Press CTRL+C to quit)
Traceback (most recent call last):
  File "app.py", line 77, in <module>
    main()
  File "app.py", line 74, in main
    app.run(host=HOST, port=PORT,debug=False)
  File "/Library/Frameworks/Python.framework/Versions/2.7/lib/python2.7/site-packages/flask/app.py", line 772, in run
    run_simple(host, port, self, **options)
  File "/Library/Frameworks/Python.framework/Versions/2.7/lib/python2.7/site-packages/werkzeug/serving.py", line 625, in run_simple
    inner()
  File "/Library/Frameworks/Python.framework/Versions/2.7/lib/python2.7/site-packages/werkzeug/serving.py", line 603, in inner
    passthrough_errors, ssl_context).serve_forever()
  File "/Library/Frameworks/Python.framework/Versions/2.7/lib/python2.7/site-packages/werkzeug/serving.py", line 512, in make_server
    passthrough_errors, ssl_context)
  File "/Library/Frameworks/Python.framework/Versions/2.7/lib/python2.7/site-packages/werkzeug/serving.py", line 440, in __init__
    HTTPServer.__init__(self, (host, int(port)), handler)
  File "/Library/Frameworks/Python.framework/Versions/2.7/lib/python2.7/SocketServer.py", line 420, in __init__
    self.server_bind()
  File "/Library/Frameworks/Python.framework/Versions/2.7/lib/python2.7/BaseHTTPServer.py", line 108, in server_bind
    SocketServer.TCPServer.server_bind(self)
  File "/Library/Frameworks/Python.framework/Versions/2.7/lib/python2.7/SocketServer.py", line 434, in server_bind
    self.socket.bind(self.server_address)
  File "/Library/Frameworks/Python.framework/Versions/2.7/lib/python2.7/socket.py", line 228, in meth
    return getattr(self._sock,name)(*args)
socket.error: [Errno 48] Address already in use
 * Running on http://0.0.0.0:5000/ (Press CTRL+C to quit)
Traceback (most recent call last):
  File "app.py", line 77, in <module>
    main()
  File "app.py", line 74, in main
    app.run(host=HOST, port=PORT,debug=False)
  File "/Library/Frameworks/Python.framework/Versions/2.7/lib/python2.7/site-packages/flask/app.py", line 772, in run
    run_simple(host, port, self, **options)
  File "/Library/Frameworks/Python.framework/Versions/2.7/lib/python2.7/site-packages/werkzeug/serving.py", line 625, in run_simple
    inner()
  File "/Library/Frameworks/Python.framework/Versions/2.7/lib/python2.7/site-packages/werkzeug/serving.py", line 603, in inner
    passthrough_errors, ssl_context).serve_forever()
  File "/Library/Frameworks/Python.framework/Versions/2.7/lib/python2.7/site-packages/werkzeug/serving.py", line 512, in make_server
    passthrough_errors, ssl_context)
  File "/Library/Frameworks/Python.framework/Versions/2.7/lib/python2.7/site-packages/werkzeug/serving.py", line 440, in __init__
    HTTPServer.__init__(self, (host, int(port)), handler)
  File "/Library/Frameworks/Python.framework/Versions/2.7/lib/python2.7/SocketServer.py", line 420, in __init__
    self.server_bind()
  File "/Library/Frameworks/Python.framework/Versions/2.7/lib/python2.7/BaseHTTPServer.py", line 108, in server_bind
    SocketServer.TCPServer.server_bind(self)
  File "/Library/Frameworks/Python.framework/Versions/2.7/lib/python2.7/SocketServer.py", line 434, in server_bind
    self.socket.bind(self.server_address)
  File "/Library/Frameworks/Python.framework/Versions/2.7/lib/python2.7/socket.py", line 228, in meth
    return getattr(self._sock,name)(*args)
socket.error: [Errno 48] Address already in use
 * Running on http://0.0.0.0:5000/ (Press CTRL+C to quit)
Traceback (most recent call last):
  File "app.py", line 77, in <module>
    main()
  File "app.py", line 74, in main
    app.run(host=HOST, port=PORT,debug=False)
  File "/Library/Frameworks/Python.framework/Versions/2.7/lib/python2.7/site-packages/flask/app.py", line 772, in run
    run_simple(host, port, self, **options)
  File "/Library/Frameworks/Python.framework/Versions/2.7/lib/python2.7/site-packages/werkzeug/serving.py", line 625, in run_simple
    inner()
  File "/Library/Frameworks/Python.framework/Versions/2.7/lib/python2.7/site-packages/werkzeug/serving.py", line 603, in inner
    passthrough_errors, ssl_context).serve_forever()
  File "/Library/Frameworks/Python.framework/Versions/2.7/lib/python2.7/site-packages/werkzeug/serving.py", line 512, in make_server
    passthrough_errors, ssl_context)
  File "/Library/Frameworks/Python.framework/Versions/2.7/lib/python2.7/site-packages/werkzeug/serving.py", line 440, in __init__
    HTTPServer.__init__(self, (host, int(port)), handler)
  File "/Library/Frameworks/Python.framework/Versions/2.7/lib/python2.7/SocketServer.py", line 420, in __init__
    self.server_bind()
  File "/Library/Frameworks/Python.framework/Versions/2.7/lib/python2.7/BaseHTTPServer.py", line 108, in server_bind
    SocketServer.TCPServer.server_bind(self)
  File "/Library/Frameworks/Python.framework/Versions/2.7/lib/python2.7/SocketServer.py", line 434, in server_bind
    self.socket.bind(self.server_address)
  File "/Library/Frameworks/Python.framework/Versions/2.7/lib/python2.7/socket.py", line 228, in meth
    return getattr(self._sock,name)(*args)
socket.error: [Errno 48] Address already in use
 * Running on http://0.0.0.0:5000/ (Press CTRL+C to quit)
Traceback (most recent call last):
  File "app.py", line 77, in <module>
    main()
  File "app.py", line 74, in main
    app.run(host=HOST, port=PORT,debug=False)
  File "/Library/Frameworks/Python.framework/Versions/2.7/lib/python2.7/site-packages/flask/app.py", line 772, in run
    run_simple(host, port, self, **options)
  File "/Library/Frameworks/Python.framework/Versions/2.7/lib/python2.7/site-packages/werkzeug/serving.py", line 625, in run_simple
    inner()
  File "/Library/Frameworks/Python.framework/Versions/2.7/lib/python2.7/site-packages/werkzeug/serving.py", line 603, in inner
    passthrough_errors, ssl_context).serve_forever()
  File "/Library/Frameworks/Python.framework/Versions/2.7/lib/python2.7/site-packages/werkzeug/serving.py", line 512, in make_server
    passthrough_errors, ssl_context)
  File "/Library/Frameworks/Python.framework/Versions/2.7/lib/python2.7/site-packages/werkzeug/serving.py", line 440, in __init__
    HTTPServer.__init__(self, (host, int(port)), handler)
  File "/Library/Frameworks/Python.framework/Versions/2.7/lib/python2.7/SocketServer.py", line 420, in __init__
    self.server_bind()
  File "/Library/Frameworks/Python.framework/Versions/2.7/lib/python2.7/BaseHTTPServer.py", line 108, in server_bind
    SocketServer.TCPServer.server_bind(self)
  File "/Library/Frameworks/Python.framework/Versions/2.7/lib/python2.7/SocketServer.py", line 434, in server_bind
    self.socket.bind(self.server_address)
  File "/Library/Frameworks/Python.framework/Versions/2.7/lib/python2.7/socket.py", line 228, in meth
    return getattr(self._sock,name)(*args)
socket.error: [Errno 48] Address already in use
